```
ERROR cinder.api.middleware.fault [req-5255d513-e4e2-4f4b-97c3-4185c7925b42 req-2f096233-6602-4eb0-9775-98042fda160c edgecraft-adm admin] Caught error: <class 'novaclient.exceptions.NotAcceptable'> Version 2.89 is not supported by the API. Minimum is 2.1 and maximum is 2.88. (HTTP 406) (Request-ID: req-4de6f7b3-facb-4701-876c-1607bd219a7c): novaclient.exceptions.NotAcceptable: Version 2.89 is not supported by the API. Minimum is 2.1 and maximum is 2.88. (HTTP 406) (Request-ID: req-4de6f7b3-facb-4701-876c-1607bd219a7c)#012ERROR cinder.api.middleware.fault Traceback (most recent call last):#012ERROR cinder.api.middleware.fault   File "/usr/lib/python3/dist-packages/cinder/api/middleware/fault.py", line 84, in __call__#012ERROR cinder.api.middleware.fault     return req.get_response(self.application)#012ERROR cinder.api.middleware.fault   File "/usr/lib/python3/dist-packages/webob/request.py", line 1313, in send#012ERROR cinder.api.middleware.fault     status, headers, app_iter = self.call_application(#012ERROR cinder.api.middleware.fault   File "/usr/lib/python3/dist-packages/webob/request.py", line 1278, in call_application#012ERROR cinder.api.middleware.fault     app_iter = application(self.environ, start_response)#012ERROR cinder.api.middleware.fault   File "/usr/lib/python3/dist-packages/webob/dec.py", line 143, in __call__#012ERROR cinder.api.middleware.fault     return resp(environ, start_response)#012ERROR cinder.api.middleware.fault   File "/usr/lib/python3/dist-packages/webob/dec.py", line 129, in __call__#012ERROR cinder.api.middleware.fault     resp = self.call_func(req, *args, **kw)#012ERROR cinder.api.middleware.fault   File "/usr/lib/python3/dist-packages/webob/dec.py", line 193, in call_func#012ERROR cinder.api.middleware.fault     return self.func(req, *args, **kwargs)#012ERROR cinder.api.middleware.fault   File "/usr/lib/python3/dist-packages/osprofiler/web.py", line 112, in __call__#012ERROR cinder.api.middleware.fault     return request.get_response(self.application)#012ERROR cinder.api.middleware.fault   File "/usr/lib/python3/dist-packages/webob/request.py", line 1313, in send#012ERROR cinder.api.middleware.fault     status, headers, app_iter = self.call_application(#012ERROR cinder.api.middleware.fault   File "/usr/lib/python3/dist-packages/webob/request.py", line 1278, in call_application#012ERROR cinder.api.middleware.fault     app_iter = application(self.environ, start_response)#012ERROR cinder.api.middleware.fault   File "/usr/lib/python3/dist-packages/webob/dec.py", line 129, in __call__#012ERROR cinder.api.middleware.fault     resp = self.call_func(req, *args, **kw)#012ERROR cinder.api.middleware.fault   File "/usr/lib/python3/dist-packages/webob/dec.py", line 193, in call_func#012ERROR cinder.api.middleware.fault     return self.func(req, *args, **kwargs)#012ERROR cinder.api.middleware.fault   File "/usr/lib/python3/dist-packages/keystonemiddleware/auth_token/__init__.py", line 341, in __call__#012ERROR cinder.api.middleware.fault     response = req.get_response(self._app)#012ERROR cinder.api.middleware.fault   File "/usr/lib/python3/dist-packages/webob/request.py", line 1313, in send#012ERROR cinder.api.middleware.fault     status, headers, app_iter = self.call_application(#012ERROR cinder.api.middleware.fault   File "/usr/lib/python3/dist-packages/webob/request.py", line 1278, in call_application#012ERROR cinder.api.middleware.fault     app_iter = application(self.environ, start_response)#012ERROR cinder.api.middleware.fault   File "/usr/lib/python3/dist-packages/webob/dec.py", line 143, in __call__#012ERROR cinder.api.middleware.fault     return resp(environ, start_response)#012ERROR cinder.api.middleware.fault   File "/usr/lib/python3/dist-packages/webob/dec.py", line 143, in __call__#012ERROR cinder.api.middleware.fault     return resp(environ, start_response)#012ERROR cinder.api.middleware.fault   File "/usr/lib/python3/dist-packages/routes/middleware.py", line 141, in __call__#012ERROR cinder.api.middleware.fault     response = self.app(environ, start_response)#012ERROR cinder.api.middleware.fault   File "/usr/lib/python3/dist-packages/webob/dec.py", line 143, in __call__#012ERROR cinder.api.middleware.fault     return resp(environ, start_response)#012ERROR cinder.api.middleware.fault   File "/usr/lib/python3/dist-packages/webob/dec.py", line 129, in __call__#012ERROR cinder.api.middleware.fault     resp = self.call_func(req, *args, **kw)#012ERROR cinder.api.middleware.fault   File "/usr/lib/python3/dist-packages/webob/dec.py", line 193, in call_func#012ERROR cinder.api.middleware.fault     return self.func(req, *args, **kwargs)#012ERROR cinder.api.middleware.fault   File "/usr/lib/python3/dist-packages/cinder/api/openstack/wsgi.py", line 837, in __call__#012ERROR cinder.api.middleware.fault     return self._process_stack(request, action, action_args,#012ERROR cinder.api.middleware.fault   File "/usr/lib/python3/dist-packages/cinder/api/openstack/wsgi.py", line 898, in _process_stack#012ERROR cinder.api.middleware.fault     action_result = self.dispatch(meth, request, action_args)#012ERROR cinder.api.middleware.fault   File "/usr/lib/python3/dist-packages/cinder/api/openstack/wsgi.py", line 993, in dispatch#012ERROR cinder.api.middleware.fault     return method(req=request, **action_args)#012ERROR cinder.api.middleware.fault   File "/usr/lib/python3/dist-packages/cinder/api/openstack/wsgi.py", line 1158, in version_select#012ERROR cinder.api.middleware.fault     return func.func(self, *args, **kwargs)#012ERROR cinder.api.middleware.fault   File "/usr/lib/python3/dist-packages/cinder/api/v3/attachments.py", line 282, in delete#012ERROR cinder.api.middleware.fault     attachments = self.volume_api.attachment_delete(context, attachment)#012ERROR cinder.api.middleware.fault   File "/usr/lib/python3/dist-packages/cinder/volume/api.py", line 2368, in attachment_delete#012ERROR cinder.api.middleware.fault     self.attachment_deletion_allowed(ctxt, attachment)#012ERROR cinder.api.middleware.fault   File "/usr/lib/python3/dist-packages/cinder/volume/api.py", line 2341, in attachment_deletion_allowed#012ERROR cinder.api.middleware.fault     nova_volume = nova.get_server_volume(ctxt, server_id,#012ERROR cinder.api.middleware.fault   File "/usr/lib/python3/dist-packages/cinder/compute/nova.py", line 227, in get_server_volume#012ERROR cinder.api.middleware.fault     return nova.volumes.get_server_volume(server_id, volume_id)#012ERROR cinder.api.middleware.fault   File "/usr/lib/python3/dist-packages/novaclient/v2/volumes.py", line 181, in get_server_volume#012ERROR cinder.api.middleware.fault     return self._get("/servers/%s/os-volume_attachments/%s" % (server_id,#012ERROR cinder.api.middleware.fault   File "/usr/lib/python3/dist-packages/novaclient/base.py", line 352, in _get#012ERROR cinder.api.middleware.fault     resp, body = self.api.client.get(url)#012ERROR cinder.api.middleware.fault   File "/usr/lib/python3/dist-packages/keystoneauth1/adapter.py", line 395, in get#012ERROR cinder.api.middleware.fault     return self.request(url, 'GET', **kwargs)#012ERROR cinder.api.middleware.fault   File "/usr/lib/python3/dist-packages/novaclient/client.py", line 78, in request#012ERROR cinder.api.middleware.fault     raise exceptions.from_response(resp, body, url, method)#012ERROR cinder.api.middleware.fault novaclient.exceptions.NotAcceptable: Version 2.89 is not supported by the API. Minimum is 2.1 and maximum is 2.88. (HTTP 406) (Request-ID: req-4de6f7b3-facb-4701-876c-1607bd219a7c)#012ERROR cinder.api.middleware.fault
```