## nfs 볼륨으로 인스탄스 생성시 오류 발생

```sh
Traceback (most recent call last): File "/usr/lib/python3/dist-packages/nova/compute/manager.py", line 1976, in _prep_block_device driver_block_device.attach_block_devices( File "/usr/lib/python3/dist-packages/nova/virt/block_device.py", line 874, in attach_block_devices _log_and_attach(device) File "/usr/lib/python3/dist-packages/nova/virt/block_device.py", line 871, in _log_and_attach bdm.attach(*attach_args, **attach_kwargs) File "/usr/lib/python3/dist-packages/nova/virt/block_device.py", line 757, in attach super(DriverVolSnapshotBlockDevice, self).attach( File "/usr/lib/python3/dist-packages/nova/virt/block_device.py", line 46, in wrapped ret_val = method(obj, context, *args, **kwargs) File "/usr/lib/python3/dist-packages/nova/virt/block_device.py", line 672, in attach self._do_attach(context, instance, volume, volume_api, File "/usr/lib/python3/dist-packages/nova/virt/block_device.py", line 657, in _do_attach self._volume_attach(context, volume, connector, instance, File "/usr/lib/python3/dist-packages/nova/virt/block_device.py", line 571, in _volume_attach connection_info = volume_api.attachment_update( File "/usr/lib/python3/dist-packages/nova/volume/cinder.py", line 396, in wrapper res = method(self, ctx, *args, **kwargs) File "/usr/lib/python3/dist-packages/nova/volume/cinder.py", line 447, in wrapper res = method(self, ctx, attachment_id, *args, **kwargs) File "/usr/lib/python3/dist-packages/nova/volume/cinder.py", line 875, in attachment_update LOG.error('Update attachment failed for attachment ' File "/usr/lib/python3/dist-packages/oslo_utils/excutils.py", line 227, in __exit__ self.force_reraise() File "/usr/lib/python3/dist-packages/oslo_utils/excutils.py", line 200, in force_reraise raise self.value File "/usr/lib/python3/dist-packages/nova/volume/cinder.py", line 867, in attachment_update attachment_ref = cinderclient( File "/usr/lib/python3/dist-packages/cinderclient/api_versions.py", line 423, in substitution return method.func(obj, *args, **kwargs) File "/usr/lib/python3/dist-packages/cinderclient/v3/attachments.py", line 74, in update resp = self._update('/attachments/%s' % id, body) File "/usr/lib/python3/dist-packages/cinderclient/base.py", line 312, in _update resp, body = self.api.client.put(url, body=body, **kwargs) File "/usr/lib/python3/dist-packages/cinderclient/client.py", line 220, in put return self._cs_request(url, 'PUT', **kwargs) File "/usr/lib/python3/dist-packages/cinderclient/client.py", line 205, in _cs_request return self.request(url, method, **kwargs) File "/usr/lib/python3/dist-packages/cinderclient/client.py", line 191, in request raise exceptions.from_response(resp, body) cinderclient.exceptions.ClientException: Unable to update the attachment. (HTTP 500) (Request-ID: req-1850b55c-6fd4-419c-b3c5-e689b0144fea) During handling of the above exception, another exception occurred: Traceback (most recent call last): File "/usr/lib/python3/dist-packages/nova/compute/manager.py", line 2605, in _build_resources block_device_info = self._prep_block_device(context, instance, File "/usr/lib/python3/dist-packages/nova/compute/manager.py", line 1996, in _prep_block_device raise exception.InvalidBDM(str(ex)) nova.exception.InvalidBDM: Unable to update the attachment. (HTTP 500) (Request-ID: req-1850b55c-6fd4-419c-b3c5-e689b0144fea) During handling of the above exception, another exception occurred: Traceback (most recent call last): File "/usr/lib/python3/dist-packages/nova/compute/manager.py", line 2232, in _do_build_and_run_instance self._build_and_run_instance(context, instance, image, File "/usr/lib/python3/dist-packages/nova/compute/manager.py", line 2441, in _build_and_run_instance compute_utils.notify_about_instance_create( File "/usr/lib/python3/dist-packages/oslo_utils/excutils.py", line 227, in __exit__ self.force_reraise() File "/usr/lib/python3/dist-packages/oslo_utils/excutils.py", line 200, in force_reraise raise self.value File "/usr/lib/python3/dist-packages/nova/compute/manager.py", line 2392, in _build_and_run_instance with self._build_resources(context, instance, File "/usr/lib/python3.8/contextlib.py", line 113, in __enter__ return next(self.gen) File "/usr/lib/python3/dist-packages/nova/compute/manager.py", line 2615, in _build_resources raise exception.BuildAbortException(instance_uuid=instance.uuid, nova.exception.BuildAbortException: Build of instance 3f21cb50-42f9-4f19-bbca-8bbe3b07fb7d aborted: Unable to update the attachment. (HTTP 500) (Request-ID: req-1850b55c-6fd4-419c-b3c5-e689b0144fea)
생성됨
2023년 4월 28일 11:22 오전
```